Workbook

Sheet DETAIL 
A1: DAILY MACHINE OPERATION CHECK SHEET
A4: MONTH : | C4: SEP | D4: 2026 | G4: MACHINE: | K4: DEPT : Tooling
A6: DATE | B6: ACC FIX ASSETS | C6: CODE | D6: MACHINE | E6: CLASSIFICATION | F6: INDEX | G6: PART | H6: TIME ( h ) | J6: TOTAL TIME ( h ) | K6: WITH OPERATOR | M6: AUTOMATION | N6: P.I.C | O6: TOTAL UTILIZATION RATE OF DAY (%) | P6: % LOST TIME | Q6: REMARK
H7: START | I7: FINISH | K7: SET UP | L7: WAITING | Q7: NEW/REPAIR | R7: Quantity | S7: NOTE

Sheet Sheet1
A1: MOULDS LIST IN TPVN | S1: Danh sách khuôn đã trả
A2: Dept: Tooling | T2: \\172.23.20.215\Tooling\03. MP MOLD GROUP\MS LAN\DANH SACH KHUON TRA
A3: Updated: 11/08/2016 | L3: =COUNTIF(L5:L1126,L1124) -> 75 | M3: =COUNTIF($M$5:$M$1125,M564) -> 91
B4: NO | C4: INDEX MOLD (OLD) | D4: INDEX MOLD (NEW) | E4: PRODUCT CODE | F4: PART NO | G4: PART NAME | H4: SLIDER/CYLINDER/MOTOR | I4: CAVITY | J4: MOLD RUNNING MP | K4: MOLD RUNNING MT | L4: MOLD T.S | M4: UNUSE MOLD | N4: GRUARANTEE SHOTG | O4: MOLD MAKER | P4: MOLD SIZE W*H*L
B5: 1 | C5: TT002 | D5: TT002 | E5: =VLOOKUP(C5,#REF!,3,0) -> #REF! | F5: HF90301 | G5: Stopper Ring | I5: 8 | J5: MP | N5: 300 | O5: TPJK | P5: -
B6: =B5+1 -> 2 | C6: TT003 | D6: TT003 | E6: =VLOOKUP(C6,#REF!,3,0) -> #REF! | F6: HF90302 | G6: Stopper Ring | I6: 4 | J6: MP | N6: 300 | O6: TPJK | P6: -
B7: =B6+1 -> 3 | C7: TT004 | D7: TT004 | E7: =VLOOKUP(C7,#REF!,3,0) -> #REF! | F7: HF90303 | G7: Sleeve | I7: 4 | J7: MP | N7: 300 | O7: TPJK | P7: -
B8: =B7+1 -> 4 | C8: TT005 | D8: TT005 | E8: =VLOOKUP(C8,#REF!,3,0) -> #REF! | F8: HF90082 | G8: Over Flow Tube | H8: CYLINDER, SLIDER | I8: 2 | J8: MP | N8: 300 | O8: TPJK | P8: -
B9: =B8+1 -> 5 | C9: TT006 | D9: TT006 | E9: =VLOOKUP(C9,#REF!,3,0) -> #REF! | F9: HF90084 | G9: WL Indication Ring | H9: SLIDER | I9: 4 | J9: MP | N9: 300 | O9: TPJK | P9: -
B10: =B9+1 -> 6 | C10: TT008 | D10: TT008 | E10: =VLOOKUP(C10,#REF!,3,0) -> #REF! | F10: HF90298R | G10: Valve | H10: SLIDER | I10: 2 | J10: MP | N10: 300 | O10: TPJK | P10: -
B11: =B10+1 -> 7 | C11: TT009 | D11: TT009 | E11: =VLOOKUP(C11,#REF!,3,0) -> #REF! | F11: HF90299R-2 | G11: Valve Lid | H11: SLIDER | I11: 2 | J11: MP | N11: 300 | O11: TPJK | P11: -
B12: =B11+1 -> 8 | C12: TT010 | D12: TT010 | E12: =VLOOKUP(C12,#REF!,3,0) -> #REF! | F12: HF90538-1 | G12: Valve Body | H12: SLIDER | I12: 2 | J12: MP | N12: 300 | O12: TPJK | P12: -
B13: =B12+1 -> 9 | C13: TT020 | D13: TT020 | E13: =VLOOKUP(C13,#REF!,3,0) -> #REF! | F13: HF21010 | G13: Nut | H13: MOTOR | I13: 4 | J13: MP | N13: 300 | O13: TPJK | P13: 350*900*650
B14: =B13+1 -> 10 | C14: TT021 | D14: TT021 | E14: =VLOOKUP(C14,#REF!,3,0) -> #REF! | F14: HF90286 | G14: Pressure Reducing Valve | H14: SLIDER | I14: 2 | J14: MP | N14: 300 | O14: TPJK | P14: 350*350*370
B15: =B14+1 -> 11 | C15: TT022 | D15: TT022 | E15: =VLOOKUP(C15,#REF!,3,0) -> #REF! | F15: HF90288 | G15: Pressure Reducing Sheet | I15: 8 | J15: MP | N15: 300 | O15: TPJK | P15: 200*240*250
B16: =B15+1 -> 12 | C16: TT023 | D16: TT023 | E16: =VLOOKUP(C16,#REF!,3,0) -> #REF! | F16: HF90295 | G16: Cap | H16: MOTOR | I16: 8 | J16: MP | N16: 300 | O16: TPJK | P16: 350*900*650
B17: =B16+1 -> 13 | C17: TT024 | D17: TT024 | E17: =VLOOKUP(C17,#REF!,3,0) -> #REF! | F17: HF90592R | G17: Diapharagm Supporter | H17: SLIDER | I17: 4 | J17: MP | N17: 300 | O17: TPJK | P17: 198*250*237
B18: =B17+1 -> 14 | C18: TT027 | D18: TT027 | E18: =VLOOKUP(C18,#REF!,3,0) -> #REF! | F18: HF1A004 | G18: Tank | H18: SLIDER | I18: 1 | J18: MP | N18: 300 | O18: Supplied by customer | P18: -
B19: =B18+1 -> 15 | C19: TT028 | D19: TT028 | E19: =VLOOKUP(C19,#REF!,3,0) -> #REF! | F19: HF9A093 | G19: Ball Tap Body | H19: SLIDER | I19: 2 | M19: UNUSE MOLD | N19: 300 | O19: Supplied by customer | P19: 450*360*500
B20: =B19+1 -> 16 | C20: TT030 | D20: TT030 | E20: =VLOOKUP(C20,#REF!,3,0) -> #REF! | F20: HF21016 | G20: Nut 18 | H20: MOTOR | I20: 2 | J20: MP | N20: 300 | O20: TPJK | P20: 250*650*230
B21: =B20+1 -> 17 | C21: TT031 | D21: TT031 | E21: =VLOOKUP(C21,#REF!,3,0) -> #REF! | G21: Bag Nut | H21: MOTOR | I21: 2 | M21: UNUSE MOLD | N21: 300 | O21: TPJK | P21: 300*340*640
B22: =B21+1 -> 18 | C22: TT033 | D22: TT033 | E22: =VLOOKUP(C22,#REF!,3,0) -> #REF! | F22: HF90545 | G22: Retfying Net | H22: MOTOR | I22: 2 | J22: MP | N22: 300 | O22: TPK | P22: 300*630*340
B23: =B22+1 -> 19 | C23: TT034 | D23: TT034 | E23: =VLOOKUP(C23,#REF!,3,0) -> #REF! | F23: HF9A090R | G23: Floating Ball | H23: SLIDER | I23: 2 | J23: MP | N23: 300 | O23: TPJK | P23: 400*500*370
B24: =B23+1 -> 20 | C24: TT035 | D24: TT035 | E24: =VLOOKUP(C24,#REF!,3,0) -> #REF! | F24: HF9A091 | G24: Float | H24: SLIDER | I24: 2 | J24: MP | N24: 300 | O24: TPK | P24: 280*350*290
B25: =B24+1 -> 21 | C25: TT039 | D25: TT039 | E25: =VLOOKUP(C25,#REF!,3,0) -> #REF! | G25: Hook | I25: 2 | J25: MP | N25: 300 | O25: TPJ | P25: 230*250*250
B26: =B25+1 -> 22 | C26: TT040 | D26: TT040 | E26: =VLOOKUP(C26,#REF!,3,0) -> #REF! | G26: Slector Valve | H26: SLIDER | I26: 2 | J26: MP | N26: 300 | O26: TPJ | P26: 280*250*250
B27: =B26+1 -> 23 | C27: TT042 | D27: TT042 | E27: =VLOOKUP(C27,#REF!,3,0) -> #REF! | F27: HF9A 116 | G27: Lever | H27: SLIDER | I27: 2 | J27: MP | N27: 300 | O27: TPJ | P27: 250*350*360
B28: =B27+1 -> 24 | C28: TT043 | D28: TT043 | E28: =VLOOKUP(C28,#REF!,3,0) -> #REF! | F28: HF9A117R | G28: Packing | I28: 2 | J28: MP | N28: 300 | O28: TPJK | P28: 250*250*230
B29: =B28+1 -> 25 | C29: TT044 | D29: TT044 | E29: =VLOOKUP(C29,#REF!,3,0) -> #REF! | G29: Fitting | I29: 2 | J29: MP | N29: 300 | O29: TPJ | P29: 200*200*220
B30: =B29+1 -> 26 | C30: TT045 | D30: TT045 | E30: =VLOOKUP(C30,#REF!,3,0) -> #REF! | G30: Close Cover | I30: 2 | J30: MP | N30: 300 | O30: TPJ | P30: 450*550*500
B31: =B30+1 -> 27 | C31: TT046 | D31: TT046 | E31: =VLOOKUP(C31,#REF!,3,0) -> #REF! | F31: HF9A129 | G31: Cover | I31: 2 | J31: MP | N31: 300 | O31: TPJK | P31: 350*450*400
B32: =B31+1 -> 28 | C32: TT049 | D32: TT049 | E32: =VLOOKUP(C32,#REF!,3,0) -> #REF! | F32: HF9A251 | G32: Spindle | H32: SLIDER | I32: 2 | J32: MP | N32: 300 | O32: TPJK | P32: 300*450*380
B33: =B32+1 -> 29 | C33: TT056 | D33: TT056 | E33: =VLOOKUP(C33,#REF!,3,0) -> #REF! | G33: Water Pipe | H33: SLIDER, MOTOR, CYLINDER | I33: 1 | J33: MP | N33: 300 | O33: TPJ | P33: 400*1100*500
B34: =B33+1 -> 30 | C34: TT065 | D34: TT065 | E34: =VLOOKUP(C34,#REF!,3,0) -> #REF! | F34: 97E 02 | G34: Shower Head Body | H34: CYLINDER, SLIDER | I34: 2 | J34: MP | N34: 300 | O34: Supplied by customer | P34: 700*950*600
B35: =B34+1 -> 31 | C35: TT067 | D35: TT067 | E35: =VLOOKUP(C35,#REF!,3,0) -> #REF! | F35: 97D 94 | G35: Orifice Shaft | H35: SLIDER | I35: 4 | J35: MP | N35: 300 | O35: TPJK | P35: 320*500*290
B36: =B35+1 -> 32 | C36: TT068 | D36: TT068 | E36: =VLOOKUP(C36,#REF!,3,0) -> #REF! | F36: 97D 95 | G36: Spread Plate Packing | H36: SLIDER | I36: 2 | J36: MP | N36: 300 | O36: TPJK | P36: 300*400*360
B37: =B36+1 -> 33 | C37: TT069 | D37: TT069 | E37: =VLOOKUP(C37,#REF!,3,0) -> #REF! | F37: 97D 96 | G37: Shaft | H37: SLIDER | I37: 4 | J37: MP | N37: 300 | O37: TPJK | P37: 230*300*230
B38: =B37+1 -> 34 | C38: TT070 | D38: TT070 | E38: =VLOOKUP(C38,#REF!,3,0) -> #REF! | F38: 97D 98 | G38: Packing | I38: 2 | J38: MP | N38: 300 | O38: TPJK | P38: 300*350*280
B39: =B38+1 -> 35 | C39: TT071 | D39: TT071 | E39: =VLOOKUP(C39,#REF!,3,0) -> #REF! | F39: 97D 99 | G39: Connecter | H39: MOTOR, SLIDER | I39: 2 | J39: MP | N39: 300 | O39: TPJK | P39: 300*900*400
B40: =B39+1 -> 36 | C40: TT072 | D40: TT072 | E40: =VLOOKUP(C40,#REF!,3,0) -> #REF! | F40: 97E 01 | G40: Spray Face | H40: MOTOR, SLIDER | I40: 2 | J40: MP | N40: 300 | O40: TPJK | P40: 350*900*400
...

Sheet NAME INDEX
C2: MOLD INDEX | D2: cn217 | E2: K1
B4: NO | C4: CODE | D4: NAME M/C | E4: TOTAL TIME (H)
E5: =SUBTOTAL(9,E6:E101) -> #REF!
B6: 1 | C6: MC01 | D6: EDM AG40L | E6: =SUMIFS('DETAIL '!#REF!,'DETAIL '!#REF!,'NAME INDEX'!$D$2,'DETAIL '!#REF!,'NAME INDEX'!C6,'DETAIL '!#REF!,'NAME INDEX'!$E$2) -> #REF!
B7: 2 | C7: MC02 | D7: EDM FORM 300 | E7: =SUMIFS('DETAIL '!#REF!,'DETAIL '!#REF!,'NAME INDEX'!$D$2,'DETAIL '!#REF!,'NAME INDEX'!C7,'DETAIL '!#REF!,'NAME INDEX'!$E$2) -> #REF!
B8: 3 | C8: MC03 | D8: EDM AG60L | E8: =SUMIFS('DETAIL '!#REF!,'DETAIL '!#REF!,'NAME INDEX'!$D$2,'DETAIL '!#REF!,'NAME INDEX'!C8,'DETAIL '!#REF!,'NAME INDEX'!$E$2) -> #REF!
B9: 4 | C9: MC04 | D9: ROBODRILL | E9: =SUMIFS('DETAIL '!#REF!,'DETAIL '!#REF!,'NAME INDEX'!$D$2,'DETAIL '!#REF!,'NAME INDEX'!C9,'DETAIL '!#REF!,'NAME INDEX'!$E$2) -> #REF!
B10: 5 | C10: MC05 | D10: GEAR HOBBING MC | E10: =SUMIFS('DETAIL '!#REF!,'DETAIL '!#REF!,'NAME INDEX'!$D$2,'DETAIL '!#REF!,'NAME INDEX'!C10,'DETAIL '!#REF!,'NAME INDEX'!$E$2) -> #REF!
B11: 6 | C11: MC06 | D11: WIRE CUT LN2W | E11: =SUMIFS('DETAIL '!#REF!,'DETAIL '!#REF!,'NAME INDEX'!$D$2,'DETAIL '!#REF!,'NAME INDEX'!C11,'DETAIL '!#REF!,'NAME INDEX'!$E$2) -> #REF!
B12: 7 | C12: MC07 | D12: VERTICAL MC CENTER | E12: =SUMIFS('DETAIL '!#REF!,'DETAIL '!#REF!,'NAME INDEX'!$D$2,'DETAIL '!#REF!,'NAME INDEX'!C12,'DETAIL '!#REF!,'NAME INDEX'!$E$2) -> #REF!
B13: 8 | C13: MC08 | D13: MILLING SHIZOUKA | E13: =SUMIFS('DETAIL '!#REF!,'DETAIL '!#REF!,'NAME INDEX'!$D$2,'DETAIL '!#REF!,'NAME INDEX'!C13,'DETAIL '!#REF!,'NAME INDEX'!$E$2) -> #REF!
B14: 9 | C14: MC09 | D14: MILLING KE55 | E14: =SUMIFS('DETAIL '!#REF!,'DETAIL '!#REF!,'NAME INDEX'!$D$2,'DETAIL '!#REF!,'NAME INDEX'!C14,'DETAIL '!#REF!,'NAME INDEX'!$E$2) -> #REF!
B15: 10 | C15: MC10 | D15: CNC LATHE | E15: =SUMIFS('DETAIL '!#REF!,'DETAIL '!#REF!,'NAME INDEX'!$D$2,'DETAIL '!#REF!,'NAME INDEX'!C15,'DETAIL '!#REF!,'NAME INDEX'!$E$2) -> #REF!
B16: 11 | C16: MC11 | D16: LATHE LR55A | E16: =SUMIFS('DETAIL '!#REF!,'DETAIL '!#REF!,'NAME INDEX'!$D$2,'DETAIL '!#REF!,'NAME INDEX'!C16,'DETAIL '!#REF!,'NAME INDEX'!$E$2) -> #REF!
B17: 12 | C17: MC12 | D17: LATHE TAKISAWA | E17: =SUMIFS('DETAIL '!#REF!,'DETAIL '!#REF!,'NAME INDEX'!$D$2,'DETAIL '!#REF!,'NAME INDEX'!C17,'DETAIL '!#REF!,'NAME INDEX'!$E$2) -> #REF!
... B30: 25 | C30: MC23 | D30: CAM NX10 | E30: =SUMIFS('DETAIL '!#REF!,'DETAIL '!#REF!,'NAME INDEX'!$D$2,'DETAIL '!#REF!,'NAME INDEX'!C30,'DETAIL '!#REF!,'NAME INDEX'!$E$2) -> #REF!
B31: 26 | E31: =SUMIFS('DETAIL '!#REF!,'DETAIL '!#REF!,'NAME INDEX'!$D$2,'DETAIL '!#REF!,'NAME INDEX'!C31,'DETAIL '!#REF!,'NAME INDEX'!$E$2) -> #REF!
B32: 27 | E32: =SUMIFS('DETAIL '!#REF!,'DETAIL '!#REF!,'NAME INDEX'!$D$2,'DETAIL '!#REF!,'NAME INDEX'!C32,'DETAIL '!#REF!,'NAME INDEX'!$E$2) -> #REF!
E787: 1 | F787: FX212 | H787: MOVING PIN P1 | I787: 8.3 | J787: 9.3 | L787: 0.16666667 | M787: 0.83333333 | Q787: =SUM(K787:K789)*100/20 -> 0
E788: 1 | F788: FX244 | H788: FIXING CAVITY | I788: 9.3 | J788: 12 | L788: 0.25 | M788: =2+0.25 -> 2.25
E789: 1 | F789: KC023 | H789: MASTER GEAR | I789: 13.3 | J789: 15 | L789: 0.083333333 | M789: =1+0.416666666666667 -> 1.4166667
E974: 1 | F974: FX500 | H974: SLDIER PIN | I974: 8.3 | J974: 10.3 | M974: 2 | O974: TUNG
E975: 1 | F975: CN189 | H975: FIXING PIN H1 | I975: 9 | J975: 12 | M975: 3 | O975: OANH
E976: 1 | F976: CN153 | H976: MOVING PIN P1 | I976: 9.3 | J976: 12 | M976: 2.5 | O976: HUONG
E977: 1 | F977: CN032 | H977: MOVIGM GEAR K1 | I977: 10.3 | J977: 14.3 | M977: 3 | O977: TUNG
A978: 43209 | E978: 4 | F978: FX510 | H978: INSERT SLIDER 304C | I978: 9.3 | J978: 11.3 | M978: 3 | O978: TUNG
A979: 43209 | E979: 4 | F979: FX510 | H979: SLIDER INSERT 304-5 | I979: 9 | J979: 12 | M979: 3 | O979: OANH
A980: 43209 | E980: 4 | F980: FX510 | H980: SLIDER | I980: 13 | J980: 17 | M980: 4 | O980: OANH
A981: 43210 | E981: 1 | F981: TP072 | H981: A3 | I981: 8.3 | J981: 12 | M981: 3.5 | O981: TUNG
A982: 43210 | E982: 1 | F982: TP072 | H982: A4 | I982: 13 | J982: 17 | M982: 4 | O982: TUNG
A983: 43210 | E983: 1 | F983: CN183 | H983: MOVING PIN P1 | I983: 8.3 | J983: 11.3 | M983: 3 | O983: OANH
A984: 43210 | E984: 1 | F984: CN114 | H984: SLIDER INSERT S4 | I984: 11.3 | J984: 14.3 | M984: 3 | O984: OANH
A985: 43210 | E985: 1 | F985: TP066 | H985: MOVIGN CORE C3 | I985: 15.3 | J985: 17 | M985: 1.5 | O985: OANH
A986: 43213 | E986: 4 | F986: FX186 | H986: MOVING CORE A2 | I986: 8.3 | J986: 10.3 | M986: 2 | O986: OANH
A987: 43213 | E987: 1 | F987: FX170 | H987: FIXING INSERT H1 | I987: 10.3 | J987: 14.3 | M987: 3 | O987: OANH
A988: 43213 | E988: 4 | F988: CN114 | H988: FIXING CAVITY | I988: 14.3 | J988: 17 | M988: 2.5 | O988: OANH
A989: 43214 | E989: 1 | F989: FX372 | H989: SLIDER INSERT | I989: 8.3 | J989: 10.3 | M989: 2 | O989: OANH
... A1010: 43217 | E1010: 1 | F1010: FX501 | H1010: INSERT | I1010: 14.3 | J1010: 17 | M1010: 2.5 | O1010: OANH
A1011: 43217 | E1011: 1 | F1011: FX510 | H1011: SLIDER 307 | I1011: 8.3 | J1011: 12 | L1011: 0.5 | M1011: 1 | N1011: 2 | O1011: QUYEN | Q1011: =SUM(K1011:K1012)*100/20 -> 0
A1012: 43217 | E1012: 4 | F1012: TP133 | H1012: RUNNER PLATE | I1012: 13 | J1012: 16 | L1012: 0.5 | N1012: 2.5 | O1012: QUYEN
...
